Traceback (most recent call last):
  File "/work/apac4/miniforge3/envs/apac-hpc-xbx/lib/python3.10/runpy.py", line 196, in _run_module_as_main
    return _run_code(code, main_globals, None,
  File "/work/apac4/miniforge3/envs/apac-hpc-xbx/lib/python3.10/runpy.py", line 86, in _run_code
    exec(code, run_globals)
  File "/work/apac4/xbx/apac/hpc/hoomd-benchmarks/hoomd_benchmarks/md_pair_wca.py", line 6, in <module>
    import hoomd
  File "/work/apac4/miniforge3/envs/apac-hpc-xbx/lib/python3.10/site-packages/hoomd/__init__.py", line 60, in <module>
    from hoomd import version
  File "/work/apac4/miniforge3/envs/apac-hpc-xbx/lib/python3.10/site-packages/hoomd/version.py", line 64, in <module>
    from hoomd import _hoomd
ImportError: libtbb.so.12: cannot open shared object file: No such file or directory
Traceback (most recent call last):
  File "/work/apac4/miniforge3/envs/apac-hpc-xbx/lib/python3.10/runpy.py", line 196, in _run_module_as_main
--------------------------------------------------------------------------
Primary job  terminated normally, but 1 process returned
a non-zero exit code. Per user-direction, the job has been aborted.
--------------------------------------------------------------------------
    return _run_code(code, main_globals, None,
  File "/work/apac4/miniforge3/envs/apac-hpc-xbx/lib/python3.10/runpy.py", line 86, in _run_code
    exec(code, run_globals)
  File "/work/apac4/xbx/apac/hpc/hoomd-benchmarks/hoomd_benchmarks/md_pair_wca.py", line 6, in <module>
    import hoomd
  File "/work/apac4/miniforge3/envs/apac-hpc-xbx/lib/python3.10/site-packages/hoomd/__init__.py", line 60, in <module>
    from hoomd import version
  File "/work/apac4/miniforge3/envs/apac-hpc-xbx/lib/python3.10/site-packages/hoomd/version.py", line 64, in <module>
    from hoomd import _hoomd
ImportError: libtbb.so.12: cannot open shared object file: No such file or directory
Traceback (most recent call last):
  File "/work/apac4/miniforge3/envs/apac-hpc-xbx/lib/python3.10/runpy.py", line 196, in _run_module_as_main
    return _run_code(code, main_globals, None,
  File "/work/apac4/miniforge3/envs/apac-hpc-xbx/lib/python3.10/runpy.py", line 86, in _run_code
    exec(code, run_globals)
  File "/work/apac4/xbx/apac/hpc/hoomd-benchmarks/hoomd_benchmarks/md_pair_wca.py", line 6, in <module>
    import hoomd
  File "/work/apac4/miniforge3/envs/apac-hpc-xbx/lib/python3.10/site-packages/hoomd/__init__.py", line 60, in <module>
    from hoomd import version
  File "/work/apac4/miniforge3/envs/apac-hpc-xbx/lib/python3.10/site-packages/hoomd/version.py", line 64, in <module>
    from hoomd import _hoomd
ImportError: libtbb.so.12: cannot open shared object file: No such file or directory
Traceback (most recent call last):
  File "/work/apac4/miniforge3/envs/apac-hpc-xbx/lib/python3.10/runpy.py", line 196, in _run_module_as_main
    return _run_code(code, main_globals, None,
  File "/work/apac4/miniforge3/envs/apac-hpc-xbx/lib/python3.10/runpy.py", line 86, in _run_code
    exec(code, run_globals)
  File "/work/apac4/xbx/apac/hpc/hoomd-benchmarks/hoomd_benchmarks/md_pair_wca.py", line 6, in <module>
    import hoomd
  File "/work/apac4/miniforge3/envs/apac-hpc-xbx/lib/python3.10/site-packages/hoomd/__init__.py", line 60, in <module>
    from hoomd import version
  File "/work/apac4/miniforge3/envs/apac-hpc-xbx/lib/python3.10/site-packages/hoomd/version.py", line 64, in <module>
    from hoomd import _hoomd
ImportError: libtbb.so.12: cannot open shared object file: No such file or directory
Traceback (most recent call last):
  File "/work/apac4/miniforge3/envs/apac-hpc-xbx/lib/python3.10/runpy.py", line 196, in _run_module_as_main
    return _run_code(code, main_globals, None,
  File "/work/apac4/miniforge3/envs/apac-hpc-xbx/lib/python3.10/runpy.py", line 86, in _run_code
    exec(code, run_globals)
  File "/work/apac4/xbx/apac/hpc/hoomd-benchmarks/hoomd_benchmarks/md_pair_wca.py", line 6, in <module>
    import hoomd
  File "/work/apac4/miniforge3/envs/apac-hpc-xbx/lib/python3.10/site-packages/hoomd/__init__.py", line 60, in <module>
    from hoomd import version
  File "/work/apac4/miniforge3/envs/apac-hpc-xbx/lib/python3.10/site-packages/hoomd/version.py", line 64, in <module>
    from hoomd import _hoomd
ImportError: libtbb.so.12: cannot open shared object file: No such file or directory
Traceback (most recent call last):
  File "/work/apac4/miniforge3/envs/apac-hpc-xbx/lib/python3.10/runpy.py", line 196, in _run_module_as_main
    return _run_code(code, main_globals, None,
  File "/work/apac4/miniforge3/envs/apac-hpc-xbx/lib/python3.10/runpy.py", line 86, in _run_code
    exec(code, run_globals)
  File "/work/apac4/xbx/apac/hpc/hoomd-benchmarks/hoomd_benchmarks/md_pair_wca.py", line 6, in <module>
    import hoomd
  File "/work/apac4/miniforge3/envs/apac-hpc-xbx/lib/python3.10/site-packages/hoomd/__init__.py", line 60, in <module>
    from hoomd import version
  File "/work/apac4/miniforge3/envs/apac-hpc-xbx/lib/python3.10/site-packages/hoomd/version.py", line 64, in <module>
    from hoomd import _hoomd
ImportError: libtbb.so.12: cannot open shared object file: No such file or directory
Traceback (most recent call last):
  File "/work/apac4/miniforge3/envs/apac-hpc-xbx/lib/python3.10/runpy.py", line 196, in _run_module_as_main
    return _run_code(code, main_globals, None,
  File "/work/apac4/miniforge3/envs/apac-hpc-xbx/lib/python3.10/runpy.py", line 86, in _run_code
    exec(code, run_globals)
  File "/work/apac4/xbx/apac/hpc/hoomd-benchmarks/hoomd_benchmarks/md_pair_wca.py", line 6, in <module>
    import hoomd
  File "/work/apac4/miniforge3/envs/apac-hpc-xbx/lib/python3.10/site-packages/hoomd/__init__.py", line 60, in <module>
    from hoomd import version
  File "/work/apac4/miniforge3/envs/apac-hpc-xbx/lib/python3.10/site-packages/hoomd/version.py", line 64, in <module>
    from hoomd import _hoomd
ImportError: libtbb.so.12: cannot open shared object file: No such file or directory
Traceback (most recent call last):
  File "/work/apac4/miniforge3/envs/apac-hpc-xbx/lib/python3.10/runpy.py", line 196, in _run_module_as_main
    return _run_code(code, main_globals, None,
  File "/work/apac4/miniforge3/envs/apac-hpc-xbx/lib/python3.10/runpy.py", line 86, in _run_code
    exec(code, run_globals)
  File "/work/apac4/xbx/apac/hpc/hoomd-benchmarks/hoomd_benchmarks/md_pair_wca.py", line 6, in <module>
    import hoomd
  File "/work/apac4/miniforge3/envs/apac-hpc-xbx/lib/python3.10/site-packages/hoomd/__init__.py", line 60, in <module>
    from hoomd import version
  File "/work/apac4/miniforge3/envs/apac-hpc-xbx/lib/python3.10/site-packages/hoomd/version.py", line 64, in <module>
    from hoomd import _hoomd
ImportError: libtbb.so.12: cannot open shared object file: No such file or directory
--------------------------------------------------------------------------
mpirun detected that one or more processes exited with non-zero status, thus causing
the job to be terminated. The first process to do so was:

  Process name: [[3228,1],22]
  Exit code:    1
--------------------------------------------------------------------------
real 4.74
user 0.47
sys 0.26
